Workbook

Sheet Guia - Avaliação
C1: GUIA — AVALIAÇÃO DOS FORNECEDORES
B3: Folha explicativa da folha «Avaliação dos Fornecedores». Esta folha é só de leitura — não precisa de preencher nada aqui.
B5: O QUE É ESTA FOLHA
B6: É a avaliação de desempenho ANUAL dos fornecedores que já trabalham com a empresa. Serve para confirmar, com base no que aconteceu durante o ano, se o fornecedor continua a cumprir o que prometeu: qualidade, ambiente, segurança, quantidade entregue, prazos, preço e relação comercial. No fim regista-se o resultado: Aprovado, Na Média ou Reprovado.
B7: Para que serve: dá resposta ao requisito 8.4 da ISO 9001 (controlo dos fornecedores externos) — a empresa tem de avaliar e reavaliar periodicamente os seus fornecedores e guardar registo disso.
B8: Quando usar: uma vez por ano (ou sempre que for definida uma reavaliação), para cada fornecedor já aprovado na folha «Seleção dos Fornecedores».
B10: ONDE ESTA FOLHA ENTRA NO PROCESSO
B11: O ficheiro tem 4 folhas de trabalho. Usam-se sempre por esta ordem:
B12: PASSO 1 | D12: «Critérios de Seleção de Fornece» — registar o fornecedor candidato (nome e tipo) e dar notas de 1 a 3 aos critérios de seleção.
B13: PASSO 2 | D13: «Seleção dos Fornecedores» — introduzir o preço do fornecedor e o preço médio de mercado. A folha calcula sozinha se o fornecedor fica Aprovado, Standby ou Não Aprovado.
B14: PASSO 3 ◄ ESTÁ AQUI | D14: «Avaliação dos Fornecedores» — uma vez por ano, avaliar o desempenho real dos fornecedores com quem já trabalhamos.
B15: CONSULTA | D15: «Critério de Análise dos Forne» — tabela que explica o que significa cada nota (3 = Bom, 2 = Médio, 1 = Mau). Consulte-a sempre que tiver dúvidas na nota a dar.
B17: COMO AS FOLHAS ESTÃO LIGADAS: cada fornecedor ocupa SEMPRE A MESMA LINHA em todas as folhas. Exemplo: o fornecedor escrito na linha 6 da folha «Critérios de Seleção de Fornece» aparece automaticamente na linha 6 da «Seleção dos Fornecedores» e na linha 6 da «Avaliação dos Fornecedores». É esta ligação linha-a-linha que torna tudo automático — e é por isso que as linhas nunca podem mudar de sítio.
B19: LEGENDA — O QUE SIGNIFICA CADA TIPO DE COLUNA
B20: PREENCHER | D20: Coluna onde VOCÊ escreve. É a única parte da folha que deve ser mexida.
B21: AUTOMÁTICA (não mexer) | D21: Coluna com fórmula. O valor aparece sozinho, calculado a partir de outras células. Não escreva, não apague e não cole nada aqui.
B22: CONSULTA / CONFIGURAÇÃO | D22: Tabela de apoio: serve para ler e decidir. Só o responsável do SGI deve alterar, e apenas quando os critérios da empresa mudarem.
B24: EXPLICAÇÃO COLUNA A COLUNA
B25: Coluna | C25: Cabeçalho na folha | D25: Tipo | E25: O que significa | F25: Como preencher / como é calculado
B26: B | C26: ID do Fornecedor | D26: AUTOMÁTICA (não mexer) | E26: Número de identificação do fornecedor. | F26: Vem da coluna B da folha «Seleção dos Fornecedores». Fórmula: ='Seleção dos Fornecedores'!B6
B27: C | C27: Nome do Fornecedor | D27: AUTOMÁTICA (não mexer) | E27: Nome do fornecedor. | F27: Vem da coluna C da folha «Critérios de Seleção de Fornece». Se aparecer 0, essa linha ainda não tem fornecedor registado. Fórmula: ='Critérios de Seleção de Fornece'!C6
B28: D | C28: Qualidade | D28: PREENCHER | E28: Se o produto/serviço entregue esteve conforme durante o ano. | F28: Escreva 3, 2 ou 1. 3 = Bom: sempre conforme, sem reclamações. 2 = Médio: irregularidades esporádicas, sem histórico de reclamações. 1 = Mau: inconformidades regulares e reclamações.
B29: E | C29: Ambiente | D29: PREENCHER | E29: Comportamento ambiental do fornecedor nas entregas. | F29: Escreva 3, 2 ou 1. 3 = Bom: entrega sempre as Fichas de Dados de Segurança (FDS), embalagens recicláveis, sem derrames. 2 = Médio: só entrega a documentação quando é pedida. 1 = Mau: não entrega FDS, embalagens danificadas.
B30: F | C30: Segurança | D30: PREENCHER | E30: Cumprimento das regras de segurança, higiene e segurança no trabalho. | F30: Escreva 3, 2 ou 1. 3 = Bom: cumprimento rigoroso, sem não conformidades. 2 = Médio: falhas pontuais. 1 = Mau: falhas graves, riscos ou incumprimentos legais.
B31: G | C31: Quantidade | D31: PREENCHER | E31: Se entregou as quantidades encomendadas. | F31: Escreva 3, 2 ou 1. 3 = Bom: entrega 100% e é flexível. 2 = Médio: ligeiras diferenças. 1 = Mau: erros constantes que afetam o stock.
B32: H | C32: Cumprimento de Prazos | D32: PREENCHER | E32: Se entregou nas datas combinadas. | F32: Escreva 3, 2 ou 1. 3 = Bom: sempre pontual. 2 = Médio: atrasos pontuais. 1 = Mau: atrasos frequentes.
B33: I | C33: Avaliação de Fornecimento | D33: AUTOMÁTICA (não mexer) | E33: Média das 5 notas acima (D a H). | F33: Soma as notas de D a H e divide pelo número de notas preenchidas. Fórmula: =MÉDIA(D6:H6)
B34: J | C34: Preço | D34: AUTOMÁTICA (não mexer) | E34: Preço do fornecedor. | F34: Vem da coluna M (Preço) da folha «Seleção dos Fornecedores». Se o preço mudar, altere-o lá — aqui atualiza sozinho. Fórmula: ='Seleção dos Fornecedores'!M6
B35: K | C35: Relações Comerciais | D35: PREENCHER | E35: Como é trabalhar com o fornecedor: comunicação, rapidez de resposta, cooperação. | F35: Escreva o número da tabela de apoio «RELAÇÕES COMERCIAIS», à direita na própria folha (colunas O e P): Neutro = 2 | Bom = 3 | Ótimo = 5 A descrição de cada nível está na folha «Critério de Análise dos Forne».
B36: L | C36: VALOR (Avaliação Geral Anual) | D36: AUTOMÁTICA (não mexer) | E36: Pontuação final do ano, em percentagem. | F36: Junta três partes, cada uma com o seu peso: • 30% vem da Avaliação de Fornecimento (coluna I) • 40% vem do Preço (coluna J) • 30% vem das Relações Comerciais (coluna K) Fórmula: =((5-I6)/4)*0,3 + (J6/4)*0,4 + (K6/4)*0,3
B37: M | C37: RESULTADO FINAL | D37: ESCREVER | E37: Decisão final sobre o fornecedor. | F37: Compare o VALOR (coluna L) com a tabela «Critério de aprovação do Fornecedor» (colunas R e S) e escreva exatamente uma destas palavras: • Aprovado — se o valor for maior que 70% → a célula fica VERDE • Na Média — se estiver entre 50% e 70% → fica AMARELA • Reprovado — se for menor que 50% → fica VERMELHA Atenção: escreva «Reprovado» (e não «Não Aprovado»), porque a cor vermelha só reconhece a palavra «Reprovado».
B39: TABELAS DE APOIO À DIREITA (colunas O a S)
B40: Onde | C40: Tabela | D40: Tipo | E40: Para que serve | F40: Como usar
B41: O5:P8 | C41: Relações Comerciais | D41: CONSULTA | E41: Converte a opinião sobre a relação comercial num número. | F41: Use o número desta tabela na coluna K. Não altere a tabela.
B42: R5:S8 | C42: Critério de aprovação do Fornecedor | D42: CONSULTA | E42: Diz em que intervalo de percentagem o fornecedor é aprovado. | F42: Use-a para decidir o que escrever na coluna M. Não altere a tabela.
B43: O10 | C43: Metodologia de avaliação de riscos: OiRA | D43: CONSULTA | E43: Indica a metodologia de avaliação de riscos de referência (OiRA). | F43: Apenas informativo.
B45: PASSO A PASSO
B46: 1. Confirme que o fornecedor já aparece nas colunas B e C (ele vem automaticamente das outras folhas — não o escreva aqui).
B47: 2. Abra a folha «Critério de Análise dos Forne» ao lado, para ler o que significa cada nota.
B48: 3. Na linha do fornecedor, escreva as notas 3, 2 ou 1 nas colunas D (Qualidade), E (Ambiente), F (Segurança), G (Quantidade) e H (Prazos).
...

Sheet Avaliação dos Fornecedores
B2: TITULO | C2: AVALIAÇÃO DE FORNECEDORES
B4: FORNECEDORES | D4: QUALIDADE, AMBIENTE E SEGURANÇA | G4: QUANTIDADE | H4: CUMPRIMENTO DE PRAZOS | I4: AVALIAÇÃO GERAL | L4: AVALIAÇÃO GERAL ANUAL
B5: ID do Fornecedor | C5: Nome do Fornecedor | D5: Qualidade | E5: Ambiente | F5: Segurança | I5: Avaliação de Fornecimento | J5: Preço | K5: Relações Comerciais | L5: VALOR | M5: RESULTADO FINAL | O5: RELAÇÕES COMERCIAIS | R5: Critério de aprovação do Fornecedor
B6: ='Seleção dos Fornecedores'!B6 -> 1 | C6: ='Critérios de Seleção de Fornece'!C6 -> 0 | I6: =AVERAGE(D6:H6) -> #DIV/0! | J6: ='Seleção dos Fornecedores'!M6 -> 0 | L6: =((5-I6)/4)*0.3 + (J6/4)*0.4 + (K6/4)*0.3 -> #DIV/0! | O6: Neutro | P6: 2 | R6: Aprovado | S6: maior 70%
B7: ='Seleção dos Fornecedores'!B7 -> 2 | C7: ='Critérios de Seleção de Fornece'!C7 -> 0 | I7: =AVERAGE(D7:H7) -> #DIV/0! | J7: ='Seleção dos Fornecedores'!M7 -> 0 | L7: =((5-I7)/4)*0.5 + (J7/5)*0.3 + (K7/5)*0.2 -> #DIV/0! | O7: Bom | P7: 3 | R7: Na Média | S7: 50% a 70%
B8: ='Seleção dos Fornecedores'!B8 -> 3 | C8: ='Critérios de Seleção de Fornece'!C8 -> 0 | I8: =AVERAGE(D8:H8) -> #DIV/0! | J8: ='Seleção dos Fornecedores'!M8 -> 0 | L8: =((5-I8)/4)*0.5 + (J8/5)*0.3 + (K8/5)*0.2 -> #DIV/0! | O8: Ótimo | P8: 5 | R8: Não Aprovado | S8: menor 50%
B9: ='Seleção dos Fornecedores'!B9 -> 4 | C9: ='Critérios de Seleção de Fornece'!C9 -> 0 | I9: =AVERAGE(D9:H9) -> #DIV/0! | J9: ='Seleção dos Fornecedores'!M9 -> 0 | L9: =((5-I9)/4)*0.5 + (J9/5)*0.3 + (K9/5)*0.2 -> #DIV/0!
B10: ='Seleção dos Fornecedores'!B10 -> 5 | C10: ='Critérios de Seleção de Fornece'!C10 -> 0 | I10: =AVERAGE(D10:H10) -> #DIV/0! | J10: ='Seleção dos Fornecedores'!M10 -> 0 | L10: =((5-I10)/4)*0.3 + (J10/4)*0.4 + (K10/4)*0.3 -> #DIV/0! | O10: METOLOGIA DE AVALIAÇÃO DE RISCOS: OiRA
B11: ='Seleção dos Fornecedores'!B11 -> 6 | C11: ='Critérios de Seleção de Fornece'!C11 -> 0 | I11: =AVERAGE(D11:H11) -> #DIV/0! | J11: ='Seleção dos Fornecedores'!M11 -> 0 | L11: =((5-I11)/4)*0.3 + (J11/4)*0.4 + (K11/4)*0.3 -> #DIV/0!
B12: ='Seleção dos Fornecedores'!B12 -> 7 | C12: ='Critérios de Seleção de Fornece'!C12 -> 0 | I12: =AVERAGE(D12:H12) -> #DIV/0! | J12: ='Seleção dos Fornecedores'!M12 -> 0 | L12: =((5-I12)/4)*0.3 + (J12/4)*0.4 + (K12/4)*0.3 -> #DIV/0!
B13: ='Seleção dos Fornecedores'!B13 -> 8 | C13: ='Critérios de Seleção de Fornece'!C13 -> 0 | I13: =AVERAGE(D13:H13) -> #DIV/0! | J13: ='Seleção dos Fornecedores'!M13 -> 0 | L13: =((5-I13)/4)*0.3 + (J13/4)*0.4 + (K13/4)*0.3 -> #DIV/0!
B14: ='Seleção dos Fornecedores'!B14 -> 9 | C14: ='Critérios de Seleção de Fornece'!C14 -> 0 | I14: =AVERAGE(D14:H14) -> #DIV/0! | J14: ='Seleção dos Fornecedores'!M14 -> 0 | L14: =((5-I14)/4)*0.3 + (J14/4)*0.4 + (K14/4)*0.3 -> #DIV/0!
B15: ='Seleção dos Fornecedores'!B15 -> 10 | C15: ='Critérios de Seleção de Fornece'!C15 -> 0 | I15: =AVERAGE(D15:H15) -> #DIV/0! | J15: ='Seleção dos Fornecedores'!M15 -> 0 | L15: =((5-I15)/4)*0.3 + (J15/4)*0.4 + (K15/4)*0.3 -> #DIV/0!
B16: ='Seleção dos Fornecedores'!B16 -> 11 | C16: ='Critérios de Seleção de Fornece'!C16 -> 0 | I16: =AVERAGE(D16:H16) -> #DIV/0! | J16: ='Seleção dos Fornecedores'!M16 -> 0 | L16: =((5-I16)/4)*0.3 + (J16/4)*0.4 + (K16/4)*0.3 -> #DIV/0!
B17: ='Seleção dos Fornecedores'!B17 -> 12 | C17: ='Critérios de Seleção de Fornece'!C17 -> 0 | I17: =AVERAGE(D17:H17) -> #DIV/0! | J17: ='Seleção dos Fornecedores'!M17 -> 0 | L17: =((5-I17)/4)*0.3 + (J17/4)*0.4 + (K17/4)*0.3 -> #DIV/0!
B18: ='Seleção dos Fornecedores'!B18 -> 13 | C18: ='Critérios de Seleção de Fornece'!C18 -> 0 | I18: =AVERAGE(D18:H18) -> #DIV/0! | J18: ='Seleção dos Fornecedores'!M18 -> 0 | L18: =((5-I18)/4)*0.3 + (J18/4)*0.4 + (K18/4)*0.3 -> #DIV/0!
B19: ='Seleção dos Fornecedores'!B19 -> 14 | C19: ='Critérios de Seleção de Fornece'!C19 -> 0 | I19: =AVERAGE(D19:H19) -> #DIV/0! | J19: ='Seleção dos Fornecedores'!M19 -> 0 | L19: =((5-I19)/4)*0.3 + (J19/4)*0.4 + (K19/4)*0.3 -> #DIV/0!
B20: ='Seleção dos Fornecedores'!B20 -> 15 | C20: ='Critérios de Seleção de Fornece'!C20 -> 0 | I20: =AVERAGE(D20:H20) -> #DIV/0! | J20: ='Seleção dos Fornecedores'!M20 -> 0 | L20: =((5-I20)/4)*0.3 + (J20/4)*0.4 + (K20/4)*0.3 -> #DIV/0!
B21: ='Seleção dos Fornecedores'!B21 -> 16 | C21: ='Critérios de Seleção de Fornece'!C21 -> 0 | I21: =AVERAGE(D21:H21) -> #DIV/0! | J21: ='Seleção dos Fornecedores'!M21 -> 0 | L21: =((5-I21)/4)*0.3 + (J21/4)*0.4 + (K21/4)*0.3 -> #DIV/0!
B22: ='Seleção dos Fornecedores'!B22 -> 17 | C22: ='Critérios de Seleção de Fornece'!C22 -> 0 | I22: =AVERAGE(D22:H22) -> #DIV/0! | J22: ='Seleção dos Fornecedores'!M22 -> 0 | L22: =((5-I22)/4)*0.3 + (J22/4)*0.4 + (K22/4)*0.3 -> #DIV/0!
... B207: ='Seleção dos Fornecedores'!B207 -> 202 | C207: ='Critérios de Seleção de Fornece'!C207 -> 0 | I207: =AVERAGE(D207:H207) -> #DIV/0! | J207: ='Seleção dos Fornecedores'!M207 -> 0 | L207: =((5-I207)/4)*0.3 + (J207/4)*0.4 + (K207/4)*0.3 -> #DIV/0!

Sheet Guia - Critério de Análise
C1: GUIA — CRITÉRIO DE ANÁLISE DOS FORNECEDORES
B3: Folha explicativa da folha «Critério de Análise dos Forne». Esta folha é só de leitura — não precisa de preencher nada aqui.
B5: O QUE É ESTA FOLHA
B6: É uma tabela de CONSULTA. Não se preenche nada nela. Explica, para cada tema avaliado, o que quer dizer dar nota 3 (Bom), 2 (Médio) ou 1 (Mau) a um fornecedor.
B7: Para que serve: garantir que todas as pessoas avaliam da mesma maneira. Duas pessoas diferentes a avaliar o mesmo fornecedor devem chegar à mesma nota, porque seguem a mesma descrição — e não a opinião de cada um.
B8: Quando usar: sempre que for dar uma nota nas folhas «Critérios de Seleção de Fornece» ou «Avaliação dos Fornecedores» e tiver dúvidas.
B10: ONDE ESTA FOLHA ENTRA NO PROCESSO
B11: O ficheiro tem 4 folhas de trabalho. Usam-se sempre por esta ordem:
B12: PASSO 1 | D12: «Critérios de Seleção de Fornece» — registar o fornecedor candidato (nome e tipo) e dar notas de 1 a 3 aos critérios de seleção.
B13: PASSO 2 | D13: «Seleção dos Fornecedores» — introduzir o preço do fornecedor e o preço médio de mercado. A folha calcula sozinha se o fornecedor fica Aprovado, Standby ou Não Aprovado.
B14: PASSO 3 | D14: «Avaliação dos Fornecedores» — uma vez por ano, avaliar o desempenho real dos fornecedores com quem já trabalhamos.
B15: CONSULTA ◄ ESTÁ AQUI | D15: «Critério de Análise dos Forne» — tabela que explica o que significa cada nota (3 = Bom, 2 = Médio, 1 = Mau). Consulte-a sempre que tiver dúvidas na nota a dar.
B17: COMO AS FOLHAS ESTÃO LIGADAS: cada fornecedor ocupa SEMPRE A MESMA LINHA em todas as folhas. Exemplo: o fornecedor escrito na linha 6 da folha «Critérios de Seleção de Fornece» aparece automaticamente na linha 6 da «Seleção dos Fornecedores» e na linha 6 da «Avaliação dos Fornecedores». É esta ligação linha-a-linha que torna tudo automático — e é por isso que as linhas nunca podem mudar de sítio.
B19: LEGENDA — O QUE SIGNIFICA CADA TIPO DE COLUNA
B20: PREENCHER | D20: Coluna onde VOCÊ escreve. É a única parte da folha que deve ser mexida.
B21: AUTOMÁTICA (não mexer) | D21: Coluna com fórmula. O valor aparece sozinho, calculado a partir de outras células. Não escreva, não apague e não cole nada aqui.
B22: CONSULTA / CONFIGURAÇÃO | D22: Tabela de apoio: serve para ler e decidir. Só o responsável do SGI deve alterar, e apenas quando os critérios da empresa mudarem.
B24: EXPLICAÇÃO COLUNA A COLUNA
B25: Coluna | C25: Cabeçalho na folha | D25: Tipo | E25: O que significa | F25: Como usar
B26: B | C26: Parâmetros | D26: CONSULTA | E26: O tema que está a ser avaliado: Qualidade, Segurança, Cumprimento de Prazos, Relações Comerciais, Ambiente, Preço e Quantidade. | F26: Procure aqui o tema da coluna que está a preencher na outra folha.
B27: C | C27: Valor | D27: CONSULTA | E27: A nota em número: 3, 2 ou 1. | F27: É este número que se escreve nas outras folhas.
B28: D | C28: Significado | D28: CONSULTA | E28: O nome da nota: Bom (3), Médio (2) ou Mau (1). | F28: Ajuda a lembrar rapidamente o que cada número quer dizer.
B29: E | C29: Critério | D29: CONSULTA | E29: A descrição concreta do comportamento do fornecedor que corresponde àquela nota. | F29: Leia as 3 descrições do tema e escolha a que é mais parecida com a realidade do fornecedor.
B30: E27 | C30: Nota | D30: CONSULTA | E30: Regra geral de pontuação. | F30: A nota deve basear-se no histórico de desempenho, nas evidências documentais, na conformidade legal, na regularidade do fornecimento e no impacto na atividade da empresa — não em impressões.
B32: ONDE CADA TEMA É USADO
B33: Tema | C33: Usado em | D33: Tipo | E33: Coluna | F33: Observação
B34: 1 | C34: Qualidade | D34: CONSULTA | E34: «Avaliação dos Fornecedores» — coluna D | F34: Notas 3 / 2 / 1
B35: 2 | C35: Ambiente | D35: CONSULTA | E35: «Avaliação dos Fornecedores» — coluna E | F35: Notas 3 / 2 / 1
B36: 3 | C36: Segurança | D36: CONSULTA | E36: «Avaliação dos Fornecedores» — coluna F | F36: Notas 3 / 2 / 1
B37: 4 | C37: Quantidade | D37: CONSULTA | E37: «Avaliação dos Fornecedores» — coluna G | F37: Notas 3 / 2 / 1
B38: 5 | C38: Cumprimento de Prazos | D38: CONSULTA | E38: «Avaliação dos Fornecedores» — coluna H | F38: Notas 3 / 2 / 1
B39: 6 | C39: Relações Comerciais | D39: CONSULTA | E39: «Avaliação dos Fornecedores» — coluna K | F39: Use as descrições daqui para decidir o nível e depois o número da tabela da própria folha (Neutro = 2, Bom = 3, Ótimo = 5).
B40: 7 | C40: Preço | D40: CONSULTA | E40: Ajuda a interpretar o preço do fornecedor | F40: O preço em si é escrito na coluna M da folha «Seleção dos Fornecedores».
B42: PASSO A PASSO
B43: 1. Na outra folha, veja qual é o tema da coluna que vai preencher (ex.: «Qualidade»).
B44: 2. Aqui, encontre esse tema na coluna B (Parâmetros).
B45: 3. Leia as três descrições da coluna E (Critério).
B46: 4. Escolha a descrição que melhor corresponde ao que aconteceu com o fornecedor.
B47: 5. Escreva na outra folha o número da coluna C (Valor): 3, 2 ou 1.
B48: 6. Guarde a evidência que justifica a nota (reclamação, relatório, guia de remessa, certificado…).
...

Sheet Critério de Análise dos Forne
C2: CRITÉRIOS DE ANÁLISE
B4: Parâmetros | C4: Valor | D4: Significado | E4: Critério
B5: Qualidade | C5: 3 | D5: Bom | E5: O fornecido apresenta-se consistentemente em conformidade e não apresenta reclamações derivado da entrega
C6: 2 | D6: Médio | E6: O fornecido apresenta-se em conformidade com irregularidades esporádicas e não apresenta um histórico de reclamações
C7: 1 | D7: Mau | E7: O fornecido apresenta inconformidades regulares e um histórico de reclamações
B8: Segurança | C8: 3 | D8: Bom | E8: Cumprimento rigoroso das normas de segurança, boas práticas de higiene e ausência de não conformidades relevantes.
C9: 2 | D9: Médio | E9: O fornecedor cumpre os requisitos básicos de segurança, mas apresenta algumas falhas pontuais ou aspetos a melhorar.
C10: 1 | D10: Mau | E10: Existem falhas significativas no cumprimento das normas de segurança alimentar, higiene ou segurança no trabalho, podendo existir riscos operacionais ou incumprimentos legais
B11: Cumprimento de Prazos | C11: 3 | D11: Bom | E11: Entregas regulares, pontuais e alinhadas com os prazos estabelecidos.
C12: 2 | D12: Médio | E12: Existem atrasos pontuais ou irregularidade moderada nas entregas.
C13: 1 | D13: Mau | E13: Ocorrem atrasos frequentes ou incumprimento sistemático das datas acordadas.
B14: Relações Comerciais | C14: 3 | D14: Bom | E14: Relação comercial estável, com boa comunicação, disponibilidade e capacidade de cooperação.
C15: 2 | D15: Médio | E15: Relação comercial funcional, mas apresenta limitações na rapidez de resposta ou na resolução de situações imprevistas.
C16: 1 | D16: Mau | E16: Dificuldades de comunicação, baixa capacidade de resposta e pouca flexibilidade na gestão comercial.
B17: Ambiente | C17: 3 | D17: Bom | E17: Entrega sempre as Fichas de Dados de Segurança (FDS) e utiliza embalagens recicláveis/certificadas. Sem histórico de derrames no transporte.
C18: 2 | D18: Médio | E18: Entrega a documentação ambiental apenas quando solicitada. Embalagens em estado razoável.
C19: 1 | D19: Mau | E19: Não fornece FDS. Embalagens danificadas com risco de contaminação do solo ou rede de águas
B20: Preço | C20: 3 | D20: Bom | E20: Preços competitivos face ao mercado e boas condições de pagamento (ex: 30-60 dias)
C21: 2 | D21: Médio | E21: Preços na média de mercado, mas com pouca margem de negociação.
C22: 1 | D22: Mau | E22: Preços muito acima do mercado ou exigência de pronto pagamento.
B23: Quantidade | C23: 3 | D23: Bom | E23: Entrega 100% da quantidade encomendada. Elevada flexibilidade para ajustes de última hora.
C24: 2 | D24: Médio | E24: Ligeiras variações entre o pedido e a entrega (ex: faltam alguns itens)
C25: 1 | D25: Mau | E25: Erros constantes nas quantidades, comprometendo o stock da linha de produção.
D27: Nota | E27: A atribuição da pontuação baseia-se no histórico de desempenho do fornecedor, evidências documentais, conformidade legal, regularidade de fornecimento e impacto operacional na atividade da empresa.

Sheet Guia - Seleção
C1: GUIA — SELEÇÃO DOS FORNECEDORES
B3: Folha explicativa da folha «Seleção dos Fornecedores». Esta folha é só de leitura — não precisa de preencher nada aqui.
B5: O QUE É ESTA FOLHA
B6: É onde se decide se um fornecedor NOVO pode começar a trabalhar com a empresa. A folha junta automaticamente as notas dadas na folha «Critérios de Seleção de Fornece», compara o preço do fornecedor com o preço médio de mercado e calcula uma nota final. No fim mostra sozinha o resultado: Aprovado, Standby ou Não Aprovado.
B7: Nesta folha só tem de escrever 3 coisas: o preço médio de mercado (coluna L), o preço do fornecedor (coluna M) e, se quiser, uma observação (coluna Q). Todo o resto é automático e está bloqueado.
B9: ONDE ESTA FOLHA ENTRA NO PROCESSO
B10: O ficheiro tem 4 folhas de trabalho. Usam-se sempre por esta ordem:
B11: PASSO 1 | D11: «Critérios de Seleção de Fornece» — registar o fornecedor candidato (nome e tipo) e dar notas de 1 a 3 aos critérios de seleção.
B12: PASSO 2 ◄ ESTÁ AQUI | D12: «Seleção dos Fornecedores» — introduzir o preço do fornecedor e o preço médio de mercado. A folha calcula sozinha se o fornecedor fica Aprovado, Standby ou Não Aprovado.
B13: PASSO 3 | D13: «Avaliação dos Fornecedores» — uma vez por ano, avaliar o desempenho real dos fornecedores com quem já trabalhamos.
B14: CONSULTA | D14: «Critério de Análise dos Forne» — tabela que explica o que significa cada nota (3 = Bom, 2 = Médio, 1 = Mau). Consulte-a sempre que tiver dúvidas na nota a dar.
B16: COMO AS FOLHAS ESTÃO LIGADAS: cada fornecedor ocupa SEMPRE A MESMA LINHA em todas as folhas. Exemplo: o fornecedor escrito na linha 6 da folha «Critérios de Seleção de Fornece» aparece automaticamente na linha 6 da «Seleção dos Fornecedores» e na linha 6 da «Avaliação dos Fornecedores». É esta ligação linha-a-linha que torna tudo automático — e é por isso que as linhas nunca podem mudar de sítio.
B18: LEGENDA — O QUE SIGNIFICA CADA TIPO DE COLUNA
B19: PREENCHER | D19: Coluna onde VOCÊ escreve. É a única parte da folha que deve ser mexida.
B20: AUTOMÁTICA (não mexer) | D20: Coluna com fórmula. O valor aparece sozinho, calculado a partir de outras células. Não escreva, não apague e não cole nada aqui.
B21: CONSULTA / CONFIGURAÇÃO | D21: Tabela de apoio: serve para ler e decidir. Só o responsável do SGI deve alterar, e apenas quando os critérios da empresa mudarem.
B23: EXPLICAÇÃO COLUNA A COLUNA
B24: Coluna | C24: Cabeçalho na folha | D24: Tipo | E24: O que significa | F24: Como preencher / como é calculado
B25: B | C25: ID | D25: AUTOMÁTICA (não mexer) | E25: Número do fornecedor. | F25: Vem da coluna B da folha «Critérios de Seleção de Fornece». Fórmula: ='Critérios de Seleção de Fornece'!B6
B26: C | C26: NOME DO FORNECEDOR | D26: AUTOMÁTICA (não mexer) | E26: Nome do fornecedor. | F26: Vem da coluna C da folha «Critérios de Seleção de Fornece». Para corrigir um nome, corrija-o lá. Fórmula: ='Critérios de Seleção de Fornece'!C6
B27: D | C27: CONFORMIDADE LEGAL | D27: AUTOMÁTICA (não mexer) | E27: Nota de conformidade legal (1 a 3). | F27: Vem da média da Conformidade Legal (coluna H) da folha de critérios. Fórmula: ='Critérios de Seleção de Fornece'!H6
B28: E | C28: TRANSPORTE | D28: AUTOMÁTICA (não mexer) | E28: Nota do transporte / cadeia de frio (1 a 3). | F28: Vem da coluna I (Cadeia de frio) da folha de critérios. Fórmula: ='Critérios de Seleção de Fornece'!I6
B29: F | C29: SST | D29: AUTOMÁTICA (não mexer) | E29: Nota de Segurança e Saúde no Trabalho (1 a 3). | F29: Vem da média SST (coluna L) da folha de critérios. Fórmula: ='Critérios de Seleção de Fornece'!L6
B30: G | C30: QUALIDADE | D30: AUTOMÁTICA (não mexer) | E30: Nota de qualidade do produto (1 a 3). | F30: Vem da média de Qualidade (coluna O) da folha de critérios. Fórmula: ='Critérios de Seleção de Fornece'!O6
B31: H | C31: OPERACIONAL | D31: AUTOMÁTICA (não mexer) | E31: Nota da capacidade de fornecimento (1 a 3). | F31: Vem da coluna Q da folha de critérios. Fórmula: ='Critérios de Seleção de Fornece'!Q6
B32: I | C32: REPUTAÇÃO | D32: AUTOMÁTICA (não mexer) | E32: Nota de histórico de mercado e ética (1 a 3). | F32: Vem da média de Reputação (coluna T) da folha de critérios. Fórmula: ='Critérios de Seleção de Fornece'!T6
B33: J | C33: SUSTENTABILIDADE | D33: AUTOMÁTICA (não mexer) | E33: Nota ambiental (1 a 3). | F33: Vem da média de Sustentabilidade (coluna W) da folha de critérios. Fórmula: ='Critérios de Seleção de Fornece'!W6
B34: K | C34: MÉDIA | D34: AUTOMÁTICA (não mexer) | E34: Média das 7 notas anteriores (D a J). | F34: Soma as notas de D a J e divide pelo número de notas. Fórmula: =MÉDIA(D6:J6)
B35: L | C35: VALOR — Média (Ind) | D35: PREENCHER | E35: Preço médio praticado no mercado (na indústria) para o mesmo produto ou serviço. | F35: Escreva só o número (sem «€»), na mesma unidade do preço do fornecedor (ex.: €/kg, €/unidade, €/mês). Pode obtê-lo, por exemplo, a partir de orçamentos de outros fornecedores.
... B40: Q | C40: OBSERVAÇÃO | D40: PREENCHER | E40: Espaço livre para notas. | F40: Opcional. Exemplos: motivo da decisão, documento em falta, condições negociadas, data prevista para reavaliar.
B42: TABELAS DE APOIO À DIREITA (colunas S e T)
B43: Onde | C43: Tabela | D43: Tipo | E43: Para que serve | F43: Atenção
B44: S4:T7 | C44: Critério para determinar o valor | D44: CONFIGURAÇÃO | E44: Mostra a pontuação do preço: Acima da Média = 1, Na média = 3, Abaixo da Média = 5. | F44: Não altere.
B45: S9:T12 | C45: Critério de aprovação do Fornecedor | D45: CONFIGURAÇÃO | E45: Mostra os limites: Aprovado (> 70%), Standby (50% a 70%), Não Aprovado (< 50%). | F45: Não altere: a coluna P vai buscar as palavras «Aprovado», «Standby» e «Não Aprovado» diretamente a estas células (S10, S11, S12). Mudar o texto aqui muda o resultado de todos os fornecedores.
B47: PASSO A PASSO
B48: 1. Primeiro preencha o fornecedor na folha «Critérios de Seleção de Fornece» (Passo 1). Ele aparece aqui sozinho, na mesma linha.
B49: 2. Confirme que as colunas B a K já mostram o nome e as notas do fornecedor.
B50: 3. Na coluna L escreva o preço médio de mercado.
B51: 4. Na coluna M escreva o preço do fornecedor (mesma unidade da coluna L).
B52: 5. Veja o resultado na coluna P: verde = Aprovado, amarelo = Standby, vermelho = Não Aprovado.
...

Sheet Seleção dos Fornecedores
C2: SELEÇÃO DOS FORNECEDORES
B4: ID | C4: NOME DO FORNECEDOR | D4: CONFORMIDADE LEGAL | E4: TRANSPORTE | F4: SST | G4: QUALIDADE | H4: OPERACIONAL | I4: REPUTAÇÃO | J4: SUSTENTABILIDADE | K4: MÉDIA | L4: VALOR | O4: NOTA FINAL | Q4: OBSERVAÇÃO | S4: Critério ara determinar o valor
L5: Média (Ind) | M5: Preço | N5: CRITÉRIO DE VALOR | O5: VALOR | P5: RESULTADO | S5: Acima da Média | T5: 1
B6: ='Critérios de Seleção de Fornece'!B6 -> 1 | C6: ='Critérios de Seleção de Fornece'!C6 -> 0 | D6: ='Critérios de Seleção de Fornece'!H6 -> 0 | E6: ='Critérios de Seleção de Fornece'!I6 -> 0 | F6: ='Critérios de Seleção de Fornece'!L6 -> #DIV/0! | G6: ='Critérios de Seleção de Fornece'!O6 -> #DIV/0! | H6: ='Critérios de Seleção de Fornece'!Q6 -> 0 | I6: ='Critérios de Seleção de Fornece'!T6 -> #DIV/0! | J6: ='Critérios de Seleção de Fornece'!W6 -> #DIV/0! | K6: =AVERAGE(D6:J6) -> #DIV/0! | N6: =IF(M6>L6,1,IF(M6=L6,T6,T7)) -> 3 | O6: =((5-K6)/4) + ((N6-3)/20) -> #DIV/0! | P6: =IF(O6>=0.7,$S$10,IF(O6>=0.5,$S$11,$S$12)) -> #DIV/0! | S6: Na média | T6: 3
B7: ='Critérios de Seleção de Fornece'!B7 -> 2 | C7: ='Critérios de Seleção de Fornece'!C7 -> 0 | D7: ='Critérios de Seleção de Fornece'!H7 -> 0 | E7: ='Critérios de Seleção de Fornece'!I7 -> 0 | F7: ='Critérios de Seleção de Fornece'!L7 -> #DIV/0! | G7: ='Critérios de Seleção de Fornece'!O7 -> #DIV/0! | H7: ='Critérios de Seleção de Fornece'!Q7 -> 0 | I7: ='Critérios de Seleção de Fornece'!T7 -> #DIV/0! | J7: ='Critérios de Seleção de Fornece'!W7 -> #DIV/0! | K7: =AVERAGE(D7:J7) -> #DIV/0! | N7: =IF(M7>L7,1,IF(M7=L7,3,5)) -> 3 | O7: =((5-K7)/4) + ((N7-3)/20) -> #DIV/0! | P7: =IF(O7>=0.7,$S$10,IF(O7>=0.5,$S$11,$S$12)) -> #DIV/0! | S7: Abaixo da Média | T7: 5
B8: ='Critérios de Seleção de Fornece'!B8 -> 3 | C8: ='Critérios de Seleção de Fornece'!C8 -> 0 | D8: ='Critérios de Seleção de Fornece'!H8 -> 0 | E8: ='Critérios de Seleção de Fornece'!I8 -> 0 | F8: ='Critérios de Seleção de Fornece'!L8 -> #DIV/0! | G8: ='Critérios de Seleção de Fornece'!O8 -> #DIV/0! | H8: ='Critérios de Seleção de Fornece'!Q8 -> 0 | I8: ='Critérios de Seleção de Fornece'!T8 -> #DIV/0! | J8: ='Critérios de Seleção de Fornece'!W8 -> #DIV/0! | K8: =AVERAGE(D8:J8) -> #DIV/0! | N8: =IF(M8>L8,1,IF(M8=L8,3,5)) -> 3 | O8: =((5-K8)/4) + ((N8-3)/20) -> #DIV/0! | P8: =IF(O8>=0.7,$S$10,IF(O8>=0.5,$S$11,$S$12)) -> #DIV/0!
B9: ='Critérios de Seleção de Fornece'!B9 -> 4 | C9: ='Critérios de Seleção de Fornece'!C9 -> 0 | D9: ='Critérios de Seleção de Fornece'!H9 -> 0 | E9: ='Critérios de Seleção de Fornece'!I9 -> 0 | F9: ='Critérios de Seleção de Fornece'!L9 -> #DIV/0! | G9: ='Critérios de Seleção de Fornece'!O9 -> #DIV/0! | H9: ='Critérios de Seleção de Fornece'!Q9 -> 0 | I9: ='Critérios de Seleção de Fornece'!T9 -> #DIV/0! | J9: ='Critérios de Seleção de Fornece'!W9 -> #DIV/0! | K9: =AVERAGE(D9:J9) -> #DIV/0! | N9: =IF(M9>L9,1,IF(M9=L9,3,5)) -> 3 | O9: =((5-K9)/4) + ((N9-3)/20) -> #DIV/0! | P9: =IF(O9>=0.7,$S$10,IF(O9>=0.5,$S$11,$S$12)) -> #DIV/0! | S9: Critério de aprovação do Fornecedor
B10: ='Critérios de Seleção de Fornece'!B10 -> 5 | C10: ='Critérios de Seleção de Fornece'!C10 -> 0 | D10: ='Critérios de Seleção de Fornece'!H10 -> 0 | E10: ='Critérios de Seleção de Fornece'!I10 -> 0 | F10: ='Critérios de Seleção de Fornece'!L10 -> #DIV/0! | G10: ='Critérios de Seleção de Fornece'!O10 -> #DIV/0! | H10: ='Critérios de Seleção de Fornece'!Q10 -> 0 | I10: ='Critérios de Seleção de Fornece'!T10 -> #DIV/0! | J10: ='Critérios de Seleção de Fornece'!W10 -> #DIV/0! | K10: =AVERAGE(D10:J10) -> #DIV/0! | N10: =IF(M10>L10,1,IF(M10=L10,3,5)) -> 3 | O10: =((5-K10)/4) + ((N10-3)/20) -> #DIV/0! | P10: =IF(O10>=0.7,$S$10,IF(O10>=0.5,$S$11,$S$12)) -> #DIV/0! | S10: Aprovado | T10: maior 70%
B11: ='Critérios de Seleção de Fornece'!B11 -> 6 | C11: ='Critérios de Seleção de Fornece'!C11 -> 0 | D11: ='Critérios de Seleção de Fornece'!H11 -> 0 | E11: ='Critérios de Seleção de Fornece'!I11 -> 0 | F11: ='Critérios de Seleção de Fornece'!L11 -> #DIV/0! | G11: ='Critérios de Seleção de Fornece'!O11 -> #DIV/0! | H11: ='Critérios de Seleção de Fornece'!Q11 -> 0 | I11: ='Critérios de Seleção de Fornece'!T11 -> #DIV/0! | J11: ='Critérios de Seleção de Fornece'!W11 -> #DIV/0! | K11: =AVERAGE(D11:J11) -> #DIV/0! | N11: =IF(M11>L11,1,IF(M11=L11,3,5)) -> 3 | O11: =((5-K11)/4) + ((N11-3)/20) -> #DIV/0! | P11: =IF(O11>=0.7,$S$10,IF(O11>=0.5,$S$11,$S$12)) -> #DIV/0! | S11: Standby | T11: 50% a 70%
B12: ='Critérios de Seleção de Fornece'!B12 -> 7 | C12: ='Critérios de Seleção de Fornece'!C12 -> 0 | D12: ='Critérios de Seleção de Fornece'!H12 -> 0 | E12: ='Critérios de Seleção de Fornece'!I12 -> 0 | F12: ='Critérios de Seleção de Fornece'!L12 -> #DIV/0! | G12: ='Critérios de Seleção de Fornece'!O12 -> #DIV/0! | H12: ='Critérios de Seleção de Fornece'!Q12 -> 0 | I12: ='Critérios de Seleção de Fornece'!T12 -> #DIV/0! | J12: ='Critérios de Seleção de Fornece'!W12 -> #DIV/0! | K12: =AVERAGE(D12:J12) -> #DIV/0! | N12: =IF(M12>L12,1,IF(M12=L12,3,5)) -> 3 | O12: =((5-K12)/4) + ((N12-3)/20) -> #DIV/0! | P12: =IF(O12>=0.7,$S$10,IF(O12>=0.5,$S$11,$S$12)) -> #DIV/0! | S12: Não Aprovado | T12: menor 50%
B13: ='Critérios de Seleção de Fornece'!B13 -> 8 | C13: ='Critérios de Seleção de Fornece'!C13 -> 0 | D13: ='Critérios de Seleção de Fornece'!H13 -> 0 | E13: ='Critérios de Seleção de Fornece'!I13 -> 0 | F13: ='Critérios de Seleção de Fornece'!L13 -> #DIV/0! | G13: ='Critérios de Seleção de Fornece'!O13 -> #DIV/0! | H13: ='Critérios de Seleção de Fornece'!Q13 -> 0 | I13: ='Critérios de Seleção de Fornece'!T13 -> #DIV/0! | J13: ='Critérios de Seleção de Fornece'!W13 -> #DIV/0! | K13: =AVERAGE(D13:J13) -> #DIV/0! | N13: =IF(M13>L13,1,IF(M13=L13,3,5)) -> 3 | O13: =((5-K13)/4) + ((N13-3)/20) -> #DIV/0! | P13: =IF(O13>=0.7,$S$10,IF(O13>=0.5,$S$11,$S$12)) -> #DIV/0!
B14: ='Critérios de Seleção de Fornece'!B14 -> 9 | C14: ='Critérios de Seleção de Fornece'!C14 -> 0 | D14: ='Critérios de Seleção de Fornece'!H14 -> 0 | E14: ='Critérios de Seleção de Fornece'!I14 -> 0 | F14: ='Critérios de Seleção de Fornece'!L14 -> #DIV/0! | G14: ='Critérios de Seleção de Fornece'!O14 -> #DIV/0! | H14: ='Critérios de Seleção de Fornece'!Q14 -> 0 | I14: ='Critérios de Seleção de Fornece'!T14 -> #DIV/0! | J14: ='Critérios de Seleção de Fornece'!W14 -> #DIV/0! | K14: =AVERAGE(D14:J14) -> #DIV/0! | N14: =IF(M14>L14,1,IF(M14=L14,3,5)) -> 3 | O14: =((5-K14)/4) + ((N14-3)/20) -> #DIV/0! | P14: =IF(O14>=0.7,$S$10,IF(O14>=0.5,$S$11,$S$12)) -> #DIV/0!
B15: ='Critérios de Seleção de Fornece'!B15 -> 10 | C15: ='Critérios de Seleção de Fornece'!C15 -> 0 | D15: ='Critérios de Seleção de Fornece'!H15 -> 0 | E15: ='Critérios de Seleção de Fornece'!I15 -> 0 | F15: ='Critérios de Seleção de Fornece'!L15 -> #DIV/0! | G15: ='Critérios de Seleção de Fornece'!O15 -> #DIV/0! | H15: ='Critérios de Seleção de Fornece'!Q15 -> 0 | I15: ='Critérios de Seleção de Fornece'!T15 -> #DIV/0! | J15: ='Critérios de Seleção de Fornece'!W15 -> #DIV/0! | K15: =AVERAGE(D15:J15) -> #DIV/0! | N15: =IF(M15>L15,1,IF(M15=L15,3,5)) -> 3 | O15: =((5-K15)/4) + ((N15-3)/20) -> #DIV/0! | P15: =IF(O15>=0.7,$S$10,IF(O15>=0.5,$S$11,$S$12)) -> #DIV/0!
B16: ='Critérios de Seleção de Fornece'!B16 -> 11 | C16: ='Critérios de Seleção de Fornece'!C16 -> 0 | D16: ='Critérios de Seleção de Fornece'!H16 -> 0 | E16: ='Critérios de Seleção de Fornece'!I16 -> 0 | F16: ='Critérios de Seleção de Fornece'!L16 -> #DIV/0! | G16: ='Critérios de Seleção de Fornece'!O16 -> #DIV/0! | H16: ='Critérios de Seleção de Fornece'!Q16 -> 0 | I16: ='Critérios de Seleção de Fornece'!T16 -> #DIV/0! | J16: ='Critérios de Seleção de Fornece'!W16 -> #DIV/0! | K16: =AVERAGE(D16:J16) -> #DIV/0! | N16: =IF(M16>L16,1,IF(M16=L16,3,5)) -> 3 | O16: =((5-K16)/4) + ((N16-3)/20) -> #DIV/0! | P16: =IF(O16>=0.7,$S$10,IF(O16>=0.5,$S$11,$S$12)) -> #DIV/0!
B17: ='Critérios de Seleção de Fornece'!B17 -> 12 | C17: ='Critérios de Seleção de Fornece'!C17 -> 0 | D17: ='Critérios de Seleção de Fornece'!H17 -> 0 | E17: ='Critérios de Seleção de Fornece'!I17 -> 0 | F17: ='Critérios de Seleção de Fornece'!L17 -> #DIV/0! | G17: ='Critérios de Seleção de Fornece'!O17 -> #DIV/0! | H17: ='Critérios de Seleção de Fornece'!Q17 -> 0 | I17: ='Critérios de Seleção de Fornece'!T17 -> #DIV/0! | J17: ='Critérios de Seleção de Fornece'!W17 -> #DIV/0! | K17: =AVERAGE(D17:J17) -> #DIV/0! | N17: =IF(M17>L17,1,IF(M17=L17,3,5)) -> 3 | O17: =((5-K17)/4) + ((N17-3)/20) -> #DIV/0! | P17: =IF(O17>=0.7,$S$10,IF(O17>=0.5,$S$11,$S$12)) -> #DIV/0!
B18: ='Critérios de Seleção de Fornece'!B18 -> 13 | C18: ='Critérios de Seleção de Fornece'!C18 -> 0 | D18: ='Critérios de Seleção de Fornece'!H18 -> 0 | E18: ='Critérios de Seleção de Fornece'!I18 -> 0 | F18: ='Critérios de Seleção de Fornece'!L18 -> #DIV/0! | G18: ='Critérios de Seleção de Fornece'!O18 -> #DIV/0! | H18: ='Critérios de Seleção de Fornece'!Q18 -> 0 | I18: ='Critérios de Seleção de Fornece'!T18 -> #DIV/0! | J18: ='Critérios de Seleção de Fornece'!W18 -> #DIV/0! | K18: =AVERAGE(D18:J18) -> #DIV/0! | N18: =IF(M18>L18,1,IF(M18=L18,3,5)) -> 3 | O18: =((5-K18)/4) + ((N18-3)/20) -> #DIV/0! | P18: =IF(O18>=0.7,$S$10,IF(O18>=0.5,$S$11,$S$12)) -> #DIV/0!
B19: ='Critérios de Seleção de Fornece'!B19 -> 14 | C19: ='Critérios de Seleção de Fornece'!C19 -> 0 | D19: ='Critérios de Seleção de Fornece'!H19 -> 0 | E19: ='Critérios de Seleção de Fornece'!I19 -> 0 | F19: ='Critérios de Seleção de Fornece'!L19 -> #DIV/0! | G19: ='Critérios de Seleção de Fornece'!O19 -> #DIV/0! | H19: ='Critérios de Seleção de Fornece'!Q19 -> 0 | I19: ='Critérios de Seleção de Fornece'!T19 -> #DIV/0! | J19: ='Critérios de Seleção de Fornece'!W19 -> #DIV/0! | K19: =AVERAGE(D19:J19) -> #DIV/0! | N19: =IF(M19>L19,1,IF(M19=L19,3,5)) -> 3 | O19: =((5-K19)/4) + ((N19-3)/20) -> #DIV/0! | P19: =IF(O19>=0.7,$S$10,IF(O19>=0.5,$S$11,$S$12)) -> #DIV/0!
B20: ='Critérios de Seleção de Fornece'!B20 -> 15 | C20: ='Critérios de Seleção de Fornece'!C20 -> 0 | D20: ='Critérios de Seleção de Fornece'!H20 -> 0 | E20: ='Critérios de Seleção de Fornece'!I20 -> 0 | F20: ='Critérios de Seleção de Fornece'!L20 -> #DIV/0! | G20: ='Critérios de Seleção de Fornece'!O20 -> #DIV/0! | H20: ='Critérios de Seleção de Fornece'!Q20 -> 0 | I20: ='Critérios de Seleção de Fornece'!T20 -> #DIV/0! | J20: ='Critérios de Seleção de Fornece'!W20 -> #DIV/0! | K20: =AVERAGE(D20:J20) -> #DIV/0! | N20: =IF(M20>L20,1,IF(M20=L20,3,5)) -> 3 | O20: =((5-K20)/4) + ((N20-3)/20) -> #DIV/0! | P20: =IF(O20>=0.7,$S$10,IF(O20>=0.5,$S$11,$S$12)) -> #DIV/0!
B21: ='Critérios de Seleção de Fornece'!B21 -> 16 | C21: ='Critérios de Seleção de Fornece'!C21 -> 0 | D21: ='Critérios de Seleção de Fornece'!H21 -> 0 | E21: ='Critérios de Seleção de Fornece'!I21 -> 0 | F21: ='Critérios de Seleção de Fornece'!L21 -> #DIV/0! | G21: ='Critérios de Seleção de Fornece'!O21 -> #DIV/0! | H21: ='Critérios de Seleção de Fornece'!Q21 -> 0 | I21: ='Critérios de Seleção de Fornece'!T21 -> #DIV/0! | J21: ='Critérios de Seleção de Fornece'!W21 -> #DIV/0! | K21: =AVERAGE(D21:J21) -> #DIV/0! | N21: =IF(M21>L21,1,IF(M21=L21,3,5)) -> 3 | O21: =((5-K21)/4) + ((N21-3)/20) -> #DIV/0! | P21: =IF(O21>=0.7,$S$10,IF(O21>=0.5,$S$11,$S$12)) -> #DIV/0!
B22: ='Critérios de Seleção de Fornece'!B22 -> 17 | C22: ='Critérios de Seleção de Fornece'!C22 -> 0 | D22: ='Critérios de Seleção de Fornece'!H22 -> 0 | E22: ='Critérios de Seleção de Fornece'!I22 -> 0 | F22: ='Critérios de Seleção de Fornece'!L22 -> #DIV/0! | G22: ='Critérios de Seleção de Fornece'!O22 -> #DIV/0! | H22: ='Critérios de Seleção de Fornece'!Q22 -> 0 | I22: ='Critérios de Seleção de Fornece'!T22 -> #DIV/0! | J22: ='Critérios de Seleção de Fornece'!W22 -> #DIV/0! | K22: =AVERAGE(D22:J22) -> #DIV/0! | N22: =IF(M22>L22,1,IF(M22=L22,3,5)) -> 3 | O22: =((5-K22)/4) + ((N22-3)/20) -> #DIV/0! | P22: =IF(O22>=0.7,$S$10,IF(O22>=0.5,$S$11,$S$12)) -> #DIV/0!
B23: ='Critérios de Seleção de Fornece'!B23 -> 18 | C23: ='Critérios de Seleção de Fornece'!C23 -> 0 | D23: ='Critérios de Seleção de Fornece'!H23 -> 0 | E23: ='Critérios de Seleção de Fornece'!I23 -> 0 | F23: ='Critérios de Seleção de Fornece'!L23 -> #DIV/0! | G23: ='Critérios de Seleção de Fornece'!O23 -> #DIV/0! | H23: ='Critérios de Seleção de Fornece'!Q23 -> 0 | I23: ='Critérios de Seleção de Fornece'!T23 -> #DIV/0! | J23: ='Critérios de Seleção de Fornece'!W23 -> #DIV/0! | K23: =AVERAGE(D23:J23) -> #DIV/0! | N23: =IF(M23>L23,1,IF(M23=L23,3,5)) -> 3 | O23: =((5-K23)/4) + ((N23-3)/20) -> #DIV/0! | P23: =IF(O23>=0.7,$S$10,IF(O23>=0.5,$S$11,$S$12)) -> #DIV/0!
B24: ='Critérios de Seleção de Fornece'!B24 -> 19 | C24: ='Critérios de Seleção de Fornece'!C24 -> 0 | D24: ='Critérios de Seleção de Fornece'!H24 -> 0 | E24: ='Critérios de Seleção de Fornece'!I24 -> 0 | F24: ='Critérios de Seleção de Fornece'!L24 -> #DIV/0! | G24: ='Critérios de Seleção de Fornece'!O24 -> #DIV/0! | H24: ='Critérios de Seleção de Fornece'!Q24 -> 0 | I24: ='Critérios de Seleção de Fornece'!T24 -> #DIV/0! | J24: ='Critérios de Seleção de Fornece'!W24 -> #DIV/0! | K24: =AVERAGE(D24:J24) -> #DIV/0! | N24: =IF(M24>L24,1,IF(M24=L24,3,5)) -> 3 | O24: =((5-K24)/4) + ((N24-3)/20) -> #DIV/0! | P24: =IF(O24>=0.7,$S$10,IF(O24>=0.5,$S$11,$S$12)) -> #DIV/0!
... B305: ='Critérios de Seleção de Fornece'!B305 -> 300 | C305: ='Critérios de Seleção de Fornece'!C305 -> 0 | D305: ='Critérios de Seleção de Fornece'!H305 -> 0 | E305: ='Critérios de Seleção de Fornece'!I305 -> 0 | F305: ='Critérios de Seleção de Fornece'!L305 -> #DIV/0! | G305: ='Critérios de Seleção de Fornece'!O305 -> #DIV/0! | H305: ='Critérios de Seleção de Fornece'!Q305 -> 0 | I305: ='Critérios de Seleção de Fornece'!T305 -> #DIV/0! | J305: ='Critérios de Seleção de Fornece'!W305 -> #DIV/0! | K305: =AVERAGE(D305:J305) -> #DIV/0! | N305: =IF(M305>L305,1,IF(M305=L305,3,5)) -> 3 | O305: =((5-K305)/4) + ((N305-3)/20) -> #DIV/0! | P305: =IF(O305>=0.7,$S$10,IF(O305>=0.5,$S$11,$S$12)) -> #DIV/0!

Sheet Guia - Critérios de Seleção
C1: GUIA — CRITÉRIOS DE SELEÇÃO DOS FORNECEDORES
B3: Folha explicativa da folha «Critérios de Seleção de Fornece». Esta folha é só de leitura — não precisa de preencher nada aqui.
B5: O QUE É ESTA FOLHA
B6: É ONDE TUDO COMEÇA. É a única folha onde se escreve o nome de um fornecedor novo. Aqui regista-se o fornecedor candidato, o tipo de fornecimento, e dão-se notas a 7 grupos de critérios: Conformidade Legal, Transporte, SST, Qualidade, Operacional, Reputação e Sustentabilidade. Tudo o que escrever aqui passa automaticamente para as outras folhas.
B7: Como dar as notas: em todas as colunas de nota use apenas 1, 2 ou 3 → 1 = Ruim / Mau, 2 = Neutro / Médio, 3 = Bom (legenda «Critério de Notas» nas colunas AA e AB, e descrições na folha «Critério de Análise dos Forne»).
B8: As palavras entre parênteses nos cabeçalhos — (Obrigatório), (Importante), (Opcional) — indicam a importância do critério para quem avalia. No cálculo automático, todas as notas contam o mesmo.
B10: ONDE ESTA FOLHA ENTRA NO PROCESSO
B11: O ficheiro tem 4 folhas de trabalho. Usam-se sempre por esta ordem:
B12: PASSO 1 ◄ ESTÁ AQUI | D12: «Critérios de Seleção de Fornece» — registar o fornecedor candidato (nome e tipo) e dar notas de 1 a 3 aos critérios de seleção.
B13: PASSO 2 | D13: «Seleção dos Fornecedores» — introduzir o preço do fornecedor e o preço médio de mercado. A folha calcula sozinha se o fornecedor fica Aprovado, Standby ou Não Aprovado.
B14: PASSO 3 | D14: «Avaliação dos Fornecedores» — uma vez por ano, avaliar o desempenho real dos fornecedores com quem já trabalhamos.
B15: CONSULTA | D15: «Critério de Análise dos Forne» — tabela que explica o que significa cada nota (3 = Bom, 2 = Médio, 1 = Mau). Consulte-a sempre que tiver dúvidas na nota a dar.
B17: COMO AS FOLHAS ESTÃO LIGADAS: cada fornecedor ocupa SEMPRE A MESMA LINHA em todas as folhas. Exemplo: o fornecedor escrito na linha 6 da folha «Critérios de Seleção de Fornece» aparece automaticamente na linha 6 da «Seleção dos Fornecedores» e na linha 6 da «Avaliação dos Fornecedores». É esta ligação linha-a-linha que torna tudo automático — e é por isso que as linhas nunca podem mudar de sítio.
B19: LEGENDA — O QUE SIGNIFICA CADA TIPO DE COLUNA
B20: PREENCHER | D20: Coluna onde VOCÊ escreve. É a única parte da folha que deve ser mexida.
B21: AUTOMÁTICA (não mexer) | D21: Coluna com fórmula. O valor aparece sozinho, calculado a partir de outras células. Não escreva, não apague e não cole nada aqui.
B22: CONSULTA / CONFIGURAÇÃO | D22: Tabela de apoio: serve para ler e decidir. Só o responsável do SGI deve alterar, e apenas quando os critérios da empresa mudarem.
B24: EXPLICAÇÃO COLUNA A COLUNA
B25: Coluna | C25: Cabeçalho na folha | D25: Tipo | E25: O que significa | F25: Como preencher / como é calculado
B26: B | C26: ID | D26: AUTOMÁTICA (não mexer) | E26: Número do fornecedor (1 a 300). | F26: Os números são gerados sozinhos por uma única fórmula na célula B6, que preenche a coluna toda. Fórmula: =SEQUÊNCIA(300) Não escreva em nenhuma célula da coluna B: se escrever, a fórmula dá erro e TODOS os números de ID desaparecem.
B27: C | C27: FORNECEDOR — NOME | D27: PREENCHER | E27: Nome do fornecedor. | F27: Escreva o nome completo da empresa. Use sempre a mesma linha para o mesmo fornecedor.
B28: D | C28: FORNECEDOR — TIPO | D28: PREENCHER | E28: Tipo de produto ou serviço fornecido. | F28: Clique na célula, depois na seta que aparece, e escolha da lista: Carne, Águas, Embalagem, Energia, Transporte, Limpeza ou Equipamentos. A lista vem das células Y6:Y15.
B29: E | C29: Empresa licenciada (S/N) | D29: PREENCHER | E29: O fornecedor tem licença para exercer a atividade? | F29: Escreva SIM ou NÃO. Se escrever NÃO (ou N), as colunas seguintes da linha ficam PRETAS: o fornecedor fica eliminado e não é preciso preencher o resto.
B30: F | C30: Cumprimento HACCP (S/N) | D30: PREENCHER | E30: O fornecedor cumpre o HACCP (segurança alimentar)? | F30: Escreva SIM (fica verde) ou NÃO (fica vermelho). Se escrever NÃO (ou N), as colunas G a W da linha ficam PRETAS: o fornecedor fica eliminado.
B31: G | C31: Possui sistema de SST | D31: PREENCHER | E31: Tem um sistema de Segurança e Saúde no Trabalho? | F31: Nota 1, 2 ou 3.
B32: H | C32: CONFORMIDADE LEGAL — MÉDIA | D32: AUTOMÁTICA (não mexer) | E32: Nota do grupo Conformidade Legal. | F32: É igual à nota da coluna G. As colunas E e F (SIM/NÃO) não entram na conta porque não são números: funcionam como «filtro» — se for NÃO, o fornecedor é eliminado. Fórmula: =G6
B33: I | C33: TRANSPORTE — Cadeia de frio (Obrigatório) | D33: PREENCHER | E33: O transporte mantém a temperatura adequada (cadeia de frio)? | F33: Nota 1, 2 ou 3. Esta nota passa diretamente para a coluna TRANSPORTE da folha «Seleção dos Fornecedores».
B34: J | C34: SST — Formação dos trabalhadores (Opcional) | D34: PREENCHER | E34: Os trabalhadores do fornecedor têm formação adequada? | F34: Nota 1, 2 ou 3.
B35: K | C35: SST — Condições de higiene (Importante) | D35: PREENCHER | E35: As instalações e práticas têm boas condições de higiene? | F35: Nota 1, 2 ou 3.
B36: L | C36: SST — MÉDIA | D36: AUTOMÁTICA (não mexer) | E36: Nota do grupo SST. | F36: Média de J e K. Fórmula: =MÉDIA(J6:K6)
... B49: AA:AB | C49: Critério de Notas | D49: CONSULTA | E49: Legenda das notas. | F49: 1 = Ruim | 2 = Neutro | 3 = Bom
B51: PASSO A PASSO
B52: 1. Procure a primeira linha vazia (coluna C sem nome). O ID na coluna B já lá está.
B53: 2. Coluna C: escreva o nome do fornecedor. Coluna D: escolha o tipo na lista.
B54: 3. Colunas E e F: escreva SIM ou NÃO. Se alguma for NÃO, a linha fica preta e o fornecedor está eliminado — pare aqui.
B55: 4. Nas colunas com fundo branco (G, I, J, K, M, N, P, R, S, U, V) escreva notas 1, 2 ou 3. Na dúvida, consulte a folha «Critério de Análise dos Forne».
B56: 5. As colunas de MÉDIA (H, L, O, Q, T, W) calculam-se sozinhas.
B57: 6. Passe para a folha «Seleção dos Fornecedores» (Passo 2) e, na mesma linha, escreva o preço de mercado e o preço do fornecedor.
B59: PORQUE É QUE AS CÉLULAS ESTÃO BLOQUEADAS
B60: Esta folha está PROTEGIDA. As colunas de MÉDIA (H, L, O, Q, T e W) estão bloqueadas porque têm fórmulas: calculam a nota de cada grupo e enviam-na para a folha «Seleção dos Fornecedores». Se uma fórmula fosse apagada, a nota deixava de chegar à seleção e o resultado do fornecedor ficava errado sem ninguém perceber. Se tentar escrever numa célula bloqueada, o Excel mostra um aviso: é normal, basta carregar em OK. A coluna B (ID) também é automática: não está bloqueada, mas NÃO deve ser mexida.
...

Sheet Critérios de Seleção de Fornece
C2: CRITÉRIO DE SELEÇÃO DOS FORNECEDORES
B4: ID | C4: FORNECEDOR | E4: CONFORMIDADE LEGAL | I4: TRANSPORTE | J4: SST | M4: QUALIDADE | P4: OPERACIONAL | R4: REPUTAÇÃO | U4: SUSTENTABILIDADE
C5: NOME | D5: TIPO | E5: Empresa licenciada (S/N) | F5: Cumprimento HACCP (S/N) | G5: Possui sistema de SST | H5: MÉDIA | I5: Cadeia de frio (Obrigatório) | J5: Formação dos trabalhadores (Opcional) | K5: Condições de higiene (Importante) | L5: MÉDIA | M5: Conformidade do Produto (Obrigatório) | N5: Rastreabilidade | O5: MEDIA | P5: Capacidade de fornecimento | Q5: MÉDIA | R5: Histórico de Mercado | S5: Ética (importante) | T5: MÉDIA | U5: Ptáticas Ambientais Sustentáveis (Importante) | V5: Possui um SGA (Importante) | W5: MÉDIA
B6: {=_xlfn.SEQUENCE(300)} -> 1 | H6: =G6 -> 0 | L6: =AVERAGE(J6:K6) -> #DIV/0! | O6: =AVERAGE(M6:N6) -> #DIV/0! | Q6: =P6 -> 0 | T6: =AVERAGE(R6:S6) -> #DIV/0! | W6: =AVERAGE(U6:V6) -> #DIV/0! | Y6: Carne | AA6: Critério de Notas
B7: 2 | H7: =G7 -> 0 | L7: =AVERAGE(J7:K7) -> #DIV/0! | O7: =AVERAGE(M7:N7) -> #DIV/0! | Q7: =P7 -> 0 | T7: =AVERAGE(R7:S7) -> #DIV/0! | W7: =AVERAGE(U7:V7) -> #DIV/0! | Y7: Águas | AA7: 1 | AB7: Ruim
B8: 3 | H8: =G8 -> 0 | L8: =AVERAGE(J8:K8) -> #DIV/0! | O8: =AVERAGE(M8:N8) -> #DIV/0! | Q8: =P8 -> 0 | T8: =AVERAGE(R8:S8) -> #DIV/0! | W8: =AVERAGE(U8:V8) -> #DIV/0! | Y8: Embalagem | AA8: 2 | AB8: Neutro
B9: 4 | H9: =G9 -> 0 | L9: =AVERAGE(J9:K9) -> #DIV/0! | O9: =AVERAGE(M9:N9) -> #DIV/0! | Q9: =P9 -> 0 | T9: =AVERAGE(R9:S9) -> #DIV/0! | W9: =AVERAGE(U9:V9) -> #DIV/0! | Y9: Energia | AA9: 3 | AB9: Bom
B10: 5 | H10: =G10 -> 0 | L10: =AVERAGE(J10:K10) -> #DIV/0! | O10: =AVERAGE(M10:N10) -> #DIV/0! | Q10: =P10 -> 0 | T10: =AVERAGE(R10:S10) -> #DIV/0! | W10: =AVERAGE(U10:V10) -> #DIV/0! | Y10: Transporte
B11: 6 | H11: =G11 -> 0 | L11: =AVERAGE(J11:K11) -> #DIV/0! | O11: =AVERAGE(M11:N11) -> #DIV/0! | Q11: =P11 -> 0 | T11: =AVERAGE(R11:S11) -> #DIV/0! | W11: =AVERAGE(U11:V11) -> #DIV/0! | Y11: Carne
B12: 7 | H12: =G12 -> 0 | L12: =AVERAGE(J12:K12) -> #DIV/0! | O12: =AVERAGE(M12:N12) -> #DIV/0! | Q12: =P12 -> 0 | T12: =AVERAGE(R12:S12) -> #DIV/0! | W12: =AVERAGE(U12:V12) -> #DIV/0! | Y12: Limpeza
B13: 8 | H13: =G13 -> 0 | L13: =AVERAGE(J13:K13) -> #DIV/0! | O13: =AVERAGE(M13:N13) -> #DIV/0! | Q13: =P13 -> 0 | T13: =AVERAGE(R13:S13) -> #DIV/0! | W13: =AVERAGE(U13:V13) -> #DIV/0! | Y13: Carne
B14: 9 | H14: =G14 -> 0 | L14: =AVERAGE(J14:K14) -> #DIV/0! | O14: =AVERAGE(M14:N14) -> #DIV/0! | Q14: =P14 -> 0 | T14: =AVERAGE(R14:S14) -> #DIV/0! | W14: =AVERAGE(U14:V14) -> #DIV/0! | Y14: Transporte
B15: 10 | H15: =G15 -> 0 | L15: =AVERAGE(J15:K15) -> #DIV/0! | O15: =AVERAGE(M15:N15) -> #DIV/0! | Q15: =P15 -> 0 | T15: =AVERAGE(R15:S15) -> #DIV/0! | W15: =AVERAGE(U15:V15) -> #DIV/0! | Y15: Equipamentos
B16: 11 | H16: =G16 -> 0 | L16: =AVERAGE(J16:K16) -> #DIV/0! | O16: =AVERAGE(M16:N16) -> #DIV/0! | Q16: =P16 -> 0 | T16: =AVERAGE(R16:S16) -> #DIV/0! | W16: =AVERAGE(U16:V16) -> #DIV/0!
B17: 12 | H17: =G17 -> 0 | L17: =AVERAGE(J17:K17) -> #DIV/0! | O17: =AVERAGE(M17:N17) -> #DIV/0! | Q17: =P17 -> 0 | T17: =AVERAGE(R17:S17) -> #DIV/0! | W17: =AVERAGE(U17:V17) -> #DIV/0!
B18: 13 | H18: =G18 -> 0 | L18: =AVERAGE(J18:K18) -> #DIV/0! | O18: =AVERAGE(M18:N18) -> #DIV/0! | Q18: =P18 -> 0 | T18: =AVERAGE(R18:S18) -> #DIV/0! | W18: =AVERAGE(U18:V18) -> #DIV/0!
B19: 14 | H19: =G19 -> 0 | L19: =AVERAGE(J19:K19) -> #DIV/0! | O19: =AVERAGE(M19:N19) -> #DIV/0! | Q19: =P19 -> 0 | T19: =AVERAGE(R19:S19) -> #DIV/0! | W19: =AVERAGE(U19:V19) -> #DIV/0!
B20: 15 | H20: =G20 -> 0 | L20: =AVERAGE(J20:K20) -> #DIV/0! | O20: =AVERAGE(M20:N20) -> #DIV/0! | Q20: =P20 -> 0 | T20: =AVERAGE(R20:S20) -> #DIV/0! | W20: =AVERAGE(U20:V20) -> #DIV/0!
B21: 16 | H21: =G21 -> 0 | L21: =AVERAGE(J21:K21) -> #DIV/0! | O21: =AVERAGE(M21:N21) -> #DIV/0! | Q21: =P21 -> 0 | T21: =AVERAGE(R21:S21) -> #DIV/0! | W21: =AVERAGE(U21:V21) -> #DIV/0!
B22: 17 | H22: =G22 -> 0 | L22: =AVERAGE(J22:K22) -> #DIV/0! | O22: =AVERAGE(M22:N22) -> #DIV/0! | Q22: =P22 -> 0 | T22: =AVERAGE(R22:S22) -> #DIV/0! | W22: =AVERAGE(U22:V22) -> #DIV/0!
B23: 18 | H23: =G23 -> 0 | L23: =AVERAGE(J23:K23) -> #DIV/0! | O23: =AVERAGE(M23:N23) -> #DIV/0! | Q23: =P23 -> 0 | T23: =AVERAGE(R23:S23) -> #DIV/0! | W23: =AVERAGE(U23:V23) -> #DIV/0!
B24: 19 | H24: =G24 -> 0 | L24: =AVERAGE(J24:K24) -> #DIV/0! | O24: =AVERAGE(M24:N24) -> #DIV/0! | Q24: =P24 -> 0 | T24: =AVERAGE(R24:S24) -> #DIV/0! | W24: =AVERAGE(U24:V24) -> #DIV/0!
B25: 20 | H25: =G25 -> 0 | L25: =AVERAGE(J25:K25) -> #DIV/0! | O25: =AVERAGE(M25:N25) -> #DIV/0! | Q25: =P25 -> 0 | T25: =AVERAGE(R25:S25) -> #DIV/0! | W25: =AVERAGE(U25:V25) -> #DIV/0!
B26: 21 | H26: =G26 -> 0 | L26: =AVERAGE(J26:K26) -> #DIV/0! | O26: =AVERAGE(M26:N26) -> #DIV/0! | Q26: =P26 -> 0 | T26: =AVERAGE(R26:S26) -> #DIV/0! | W26: =AVERAGE(U26:V26) -> #DIV/0!
B27: 22 | H27: =G27 -> 0 | L27: =AVERAGE(J27:K27) -> #DIV/0! | O27: =AVERAGE(M27:N27) -> #DIV/0! | Q27: =P27 -> 0 | T27: =AVERAGE(R27:S27) -> #DIV/0! | W27: =AVERAGE(U27:V27) -> #DIV/0!
... B305: 300 | H305: =G305 -> 0 | L305: =AVERAGE(J305:K305) -> #DIV/0! | O305: =AVERAGE(M305:N305) -> #DIV/0! | Q305: =P305 -> 0 | T305: =AVERAGE(R305:S305) -> #DIV/0! | W305: =AVERAGE(U305:V305) -> #DIV/0!
